Workbook

Sheet Data
B2: Hyundai Motor Company
B4: Balance Sheet | D4: 2018 | E4: 2019 | F4: 2020 | G4: 2021 | H4: 2022 | I4: 2023 | J4: 2024 | K4: 2025
B5: Current assets | C5: Million KRW | D5: 73008101 | E5: 76082873 | F5: 83686357 | G5: 88565366 | H5: 96389273 | I5: 101724717 | J5: 115764287 | K5: 120777363
B6: Non-current assets | C6: Million KRW | D6: 107647651 | E6: 118429347 | F6: 125657855 | G6: 145381049 | H6: 159353189 | I6: 180738638 | J6: 224034142 | K6: 248067486
B7: Total assets | C7: Million KRW | D7: 180655752 | E7: 194512220 | F7: 209344212 | G7: 233946415 | H7: 255742462 | I7: 282463355 | J7: 339798429 | K7: 368844849
B8: Current liabilities | C8: Million KRW | D8: 49438414 | E8: 53314096 | F8: 59459528 | G8: 64236787 | H8: 74236472 | I8: 73362103 | J8: 79509643 | K8: 88579290
B9: Non-current liabilities | C9: Million KRW | D9: 57321328 | E9: 64832370 | F9: 73543714 | G9: 87093839 | H9: 90609445 | I9: 107291812 | J9: 140012853 | K9: 152617322
B10: Total liabilities | C10: Million KRW | D10: 106759742 | E10: 118146466 | F10: 133003242 | G10: 151330626 | H10: 164845917 | I10: 180653915 | J10: 219522496 | K10: 241196612
B11: Equity attributable to the owners of the Company | C11: Million KRW | D11: 67973969 | E11: 70065802 | F11: 69480633 | G11: 74986122 | H11: 82349287 | I11: 92497311 | J11: 109103398 | K11: 115446507
B12: Non-controlling interests | C12: Million KRW | D12: 5922041 | E12: 6299952 | F12: 6860337 | G12: 7629667 | H12: 8547258 | I12: 9312129 | J12: 11172535 | K12: 12201730
B13: Total equity | C13: Million KRW | D13: 73896010 | E13: 76365754 | F13: 76340970 | G13: 82615789 | H13: 90896545 | I13: 101809440 | J13: 120275933 | K13: 127648237
B14: Total asset growth | C14: % | D14: 1.4 | E14: 7.6700951 | F14: 7.6252238 | G14: 11.752034 | H14: 9.3166835 | I14: 10.44836 | J14: 20.298234 | K14: 8.5481325
B16: Income Statement | D16: 2018 | E16: 2019 | F16: 2020 | G16: 2021 | H16: 2022 | I16: 2023 | J16: 2024 | K16: 2025
B17: Sales | C17: Million KRW | D17: 96812609 | E17: 105746422 | F17: 103997601 | G17: 117610626 | H17: 142151469 | I17: 162663579 | J17: 175231153 | K17: 186254472
B18: Gross profit | C18: Million KRW | D18: 15142130 | E18: 17655013 | F18: 18481670 | G18: 21930495 | H18: 28271900 | I18: 33484396 | J18: 35749207 | K18: 34216836
B19: Operating profit | C19: Million KRW | D19: 2422165 | E19: 3605505 | F19: 2394671 | G19: 6678949 | H19: 9824928 | I19: 15126901 | J19: 14239592 | K19: 11467851
B20: Profit before income tax | C20: Million KRW | D20: 2529582 | E20: 4163766 | F20: 2093256 | G20: 7959562 | H20: 11181471 | I20: 17618662 | J20: 17781436 | K20: 13841903
B21: Profit for the year | C21: Million KRW | D21: 1645019 | E21: 3185646 | F21: 1924553 | G21: 5693077 | H21: 7983614 | I21: 12272301 | J21: 13229908 | K21: 10364775
B22: Profit attributable to Owners of the Company | C22: Million KRW | D22: 1508084 | E22: 2980049 | F22: 1424436 | G22: 4942356 | H22: 7364364 | I22: 11961717 | J22: 12526691 | K22: 9445987
B23: Profit attributable to Non-controlling interests | C23: Million KRW | D23: 136935 | E23: 205597 | F23: 500117 | G23: 750721 | H23: 619250 | I23: 310584 | J23: 703217 | K23: 918788
B24: Sales growth | C24: % | D24: 0.5 | E24: 9.2279436 | F24: -1.6537874 | G24: 13.089749 | H24: 20.866178 | I24: 14.429756 | J24: 7.7261143 | K24: 6.2907302
B25: Profit growth | C25: % | D25: -63.8 | E25: 93.654055 | F25: -39.586727 | G25: 195.81295 | H25: 40.233726 | I25: 53.718617 | J25: 7.8029947 | K25: -21.656485
B26: Earnings per share
B27: Basic earnings per share: Common stock | C27: KRW | D27: 5632 | E27: 11310 | F27: 5454 | G27: 18979 | H27: 28521 | I27: 45703 | J27: 47615 | K27: 36088
B28: Basic earnings per share: 1st preferred stock | C28: KRW | D28: 5681 | E28: 11355 | F28: 5502 | G28: 19002 | H28: 28207 | I28: 45535 | J28: 47369 | K28: 37851
B29: Diluted earnings per share: Common stock | C29: KRW | D29: 5632 | E29: 11310 | F29: 5454 | G29: 18979 | H29: 28521 | I29: 45703 | J29: 47615 | K29: 36088
B30: Diluted earnings per share: 1st preferred stock | C30: KRW | D30: 5681 | E30: 11355 | F30: 5502 | G30: 19002 | H30: 28207 | I30: 45535 | J30: 47369 | K30: 37851
B32: Cash Flows | D32: 2018 | E32: 2019 | F32: 2020 | G32: 2021 | H32: 2022 | I32: 2023 | J32: 2024 | K32: 2025
B33: Net cash provided by (used in) operating activities | C33: Million KRW | D33: 3764265 | E33: 419784 | F33: -409807 | G33: -1176416 | H33: 10627311 | I33: -2518760 | J33: -5661641 | K33: -5991270
B34: Net cash used in investing activities | C34: Million KRW | D34: -2415064 | E34: -5929184 | F34: -9337596 | G34: -5182579 | H34: -1203495 | I34: -8649391 | J34: -14623489 | K34: -10347129
B35: Net cash provided by (used in) financing activities | C35: Million KRW | D35: -880782 | E35: 4874926 | F35: 11352473 | G35: 8792286 | H35: -1324499 | I35: 9393371 | J35: 19493291 | K35: 15424760
B36: Net increase (decrease) in cash and cash equivalents | C36: Million KRW | D36: 292096 | E36: -431654 | F36: 1180165 | G36: 2933418 | H36: 8069325 | I36: -1698260 | J36: -151675 | K36: -654378
B37: Cash and cash equivalents, end of the year | C37: Million KRW | D37: 9113625 | E37: 8681971 | F37: 9862136 | G37: 12795554 | H37: 20864879 | I37: 19166619 | J37: 19014944 | K37: 18360566
B39: Key Ratios | D39: 2018 | E39: 2019 | F39: 2020 | G39: 2021 | H39: 2022 | I39: 2023 | J39: 2024 | K39: 2025
B40: Current Ratio | C40: % | D40: 147.67484 | E40: 142.70686 | F40: 140.74507 | G40: 137.87328 | H40: 129.84086 | I40: 138.66112 | J40: 145.59779 | K40: 136.34944
B41: Liability to equity | C41: % | D41: 144.47295 | E41: 154.71132 | F41: 174.22263 | G41: 183.17398 | H41: 181.35554 | I41: 177.44319 | J41: 182.51573 | K41: 188.95413
B42: Debt to equity | C42: % | D42: 99.2 | E42: 106.6 | F42: 119.7 | G42: 130.4754 | H42: 123.42143 | I42: 122.53084 | J42: 130.10862 | K42: 137.40091
B43: Return on sales | C43: % | D43: 1.6991785 | E43: 3.0125331 | F43: 1.8505744 | G43: 4.8406145 | H43: 5.6162726 | I43: 7.5445905 | J43: 7.5499749 | K43: 5.5648462
B44: Basic EPS | C44: KRW | D44: 5632 | E44: 11310 | F44: 5454 | G44: 18979 | H44: 28521 | I44: 45703 | J44: 47615 | K44: 36088
B46: Segment Information | D46: 2018 | E46: 2019 | F46: 2020 | G46: 2021 | H46: 2022 | I46: 2023 | J46: 2024 | K46: 2025
...

Sheet DCF Modelling
A2: Income Statement | D2: 2020 | E2: 2021 | F2: 2022 | G2: 2023 | H2: 2024 | I2: 2025 | J2: 2026 | K2: 2027 | L2: 2028 | M2: 2029 | N2: 2030
A3: Revenue | D3: 105746422 | E3: 117610626 | F3: 142527535 | G3: 162663579 | H3: 175231153 | I3: 186254470 | J3: =I3*(1+J12) -> 2.0014895e+08 | K3: =J3*(1+K12) -> 2.0159855e+08 | L3: =K3*(1+L12) -> 2.3242964e+08 | M3: =L3*(1+M12) -> 2.5479643e+08 | N3: =M3*(1+N12) -> 3.1054252e+08
A5: Cost of Sales | D5: 88091409 | E5: 95680131 | F5: 114209483 | G5: 129179183 | H5: 139481946 | I5: 152037636 | J5: =I5*(1+J19) -> 1.6778564e+08 | K5: =J5*(1+K19) -> 1.904853e+08 | L5: =K5*(1+L19) -> 2.140598e+08 | M5: =L5*(1+M19) -> 2.3741769e+08 | N5: =M5*(1+N19) -> 2.6718518e+08
A7: Days Sale Outstanding | D7: =D46/D5*360 -> 13.420491 | E7: =E46/E5*360 -> 11.841817 | F7: =F46/F5*360 -> 13.488026 | G7: =G46/G5*360 -> 13.04843 | H7: =H46/H5*360 -> 15.248629 | I7: =I46/I5*360 -> 20.364371 | J7: =AVERAGE(G7:I7) -> 16.220477 | K7: =AVERAGE(H7:J7) -> 17.277826 | L7: =AVERAGE(I7:K7) -> 17.954224 | M7: =AVERAGE(J7:L7) -> 17.150842 | N7: =AVERAGE(K7:M7) -> 17.460964
A8: Days Inventory Outstanding | D8: =D48/D5*360 -> 46.317164 | E8: =E48/E5*360 -> 43.817151 | F8: =F48/F5*360 -> 45.047378 | G8: =G48/G5*360 -> 48.491749 | H8: =H48/H5*360 -> 51.080177 | I8: =I48/I5*360 -> 48.923615 | J8: =AVERAGE(G8:I8) -> 49.498514 | K8: =AVERAGE(H8:J8) -> 49.834102 | L8: =AVERAGE(I8:K8) -> 49.418743 | M8: =AVERAGE(J8:L8) -> 49.583786 | N8: =AVERAGE(K8:M8) -> 49.612211
A9: Days Payable Outstanding | D9: =D56/D5*360 -> 35.934769 | E9: =E56/E5*360 -> 34.446983 | F9: =F56/F5*360 -> 34.033456 | G9: =G56/G5*360 -> 30.521455 | H9: =H56/H5*360 -> 32.390375 | I9: =I56/I5*360 -> 29.094502 | J9: =AVERAGE(G9:I9) -> 30.668777 | K9: =AVERAGE(H9:J9) -> 30.717885 | L9: =AVERAGE(I9:K9) -> 30.160388 | M9: =AVERAGE(J9:L9) -> 30.515683 | N9: =AVERAGE(K9:M9) -> 30.464652
A11: Normally Distributed Random Variable of Forecasted Revenue
A12: % Growth of Revenue | E12: =E3/D3-1 -> 0.11219485 | F12: =F3/E3-1 -> 0.21185933 | G12: =G3/F3-1 -> 0.14127827 | H12: =H3/G3-1 -> 0.077261143 | I12: =I3/H3-1 -> 0.06290729 | J12: =_xlfn.NORM.INV(RAND(),I14,I16) -> 0.074599458 | K12: =_xlfn.NORM.INV(RAND(),J14,J16) -> 0.0072425777 | L12: =_xlfn.NORM.INV(RAND(),K14,K16) -> 0.15293309 | M12: =_xlfn.NORM.INV(RAND(),L14,L16) -> 0.096230384 | N12: =_xlfn.NORM.INV(RAND(),M14,M16) -> 0.21878679
A14: Mean % Growth of Revenue | E14: =AVERAGE(E12) -> 0.11219485 | F14: =AVERAGE($E$12:F12) -> 0.16202709 | G14: =AVERAGE($E$12:G12) -> 0.15511082 | H14: =AVERAGE($E$12:H12) -> 0.1356484 | I14: =AVERAGE($E$12:I12) -> 0.12110018 | J14: =AVERAGE($E$12:J12) -> 0.11335006 | K14: =AVERAGE($E$12:K12) -> 0.098191847 | L14: =AVERAGE($E$12:L12) -> 0.1050345 | M14: =AVERAGE($E$12:M12) -> 0.10405627 | N14: =AVERAGE($E$12:N12) -> 0.11552932
A16: Standard Deviation of % Growth of Revenue | E16: =_xlfn.STDEV.P($E$12) -> 0 | F16: =_xlfn.STDEV.P($E$12:F12) -> 0.049832242 | G16: =_xlfn.STDEV.P($E$12:G12) -> 0.041846998 | H16: =_xlfn.STDEV.P($E$12:H12) -> 0.049494805 | I16: =_xlfn.STDEV.P($E$12:I12) -> 0.052975387 | J16: =_xlfn.STDEV.P($E$12:J12) -> 0.051371018 | K16: =_xlfn.STDEV.P($E$12:K12) -> 0.060337487 | L16: =_xlfn.STDEV.P($E$12:L12) -> 0.059273007 | M16: =_xlfn.STDEV.P($E$12:M12) -> 0.055951581 | N16: =_xlfn.STDEV.P($E$12:N12) -> 0.063262942
A18: Normally Distributed Random Variable of Forecasted Cost of Sales
A19: % Growth of Cost of Sales | E19: =E5/D5-1 -> 0.086145994 | F19: =F5/E5-1 -> 0.19365935 | G19: =G5/F5-1 -> 0.1310723 | H19: =H5/G5-1 -> 0.079755598 | I19: =I5/H5-1 -> 0.090016596 | J19: =_xlfn.NORM.INV(RAND(),I21,I23) -> 0.10357962 | K19: =_xlfn.NORM.INV(RAND(),J21,J23) -> 0.13528965 | L19: =_xlfn.NORM.INV(RAND(),K21,K23) -> 0.12376024 | M19: =_xlfn.NORM.INV(RAND(),L21,L23) -> 0.10911852 | N19: =_xlfn.NORM.INV(RAND(),M21,M23) -> 0.12538025
A21: Mean % Growth of Cost of Sales | E21: =AVERAGE(E19) -> 0.086145994 | F21: =AVERAGE($E$19:F19) -> 0.13990267 | G21: =AVERAGE($E$19:G19) -> 0.13695922 | H21: =AVERAGE($E$19:H19) -> 0.12265831 | I21: =AVERAGE($E$19:I19) -> 0.11612997 | J21: =AVERAGE($E$19:J19) -> 0.11403824 | K21: =AVERAGE($E$19:K19) -> 0.11707416 | L21: =AVERAGE($E$19:L19) -> 0.11790992 | M21: =AVERAGE($E$19:M19) -> 0.1169331 | N21: =AVERAGE($E$19:N19) -> 0.11777781
A23: Standard Deviation of % Growth of Cost of Sales | F23: =_xlfn.STDEV.P($E$21:F21) -> 0.026878339 | G23: =_xlfn.STDEV.P($E$21:G21) -> 0.024676637 | H23: =_xlfn.STDEV.P($E$21:H21) -> 0.021382617 | I23: =_xlfn.STDEV.P($E$21:I21) -> 0.019241744 | J23: =_xlfn.STDEV.P($E$21:J21) -> 0.017722487 | K23: =_xlfn.STDEV.P($E$21:K21) -> 0.016426407 | L23: =_xlfn.STDEV.P($E$21:L21) -> 0.015369624 | M23: =_xlfn.STDEV.P($E$21:M21) -> 0.014503168 | N23: =_xlfn.STDEV.P($E$21:N21) -> 0.013761339
A27: EBIT | E27: =6678949 -> 6678949 | F27: =9824928 -> 9824928 | G27: =15126901 -> 15126901 | H27: =14239592 -> 14239592 | I27: =11467851 -> 11467851 | J27: =I27*(1+J31) -> 12792560 | K27: =J27*(1+K31) -> 14120046 | L27: =K27*(1+L31) -> 25261149 | M27: =L27*(1+M31) -> 28517421 | N27: =M27*(1+N31) -> 25485773
A29: EBIT (3 Year Avg) | E29: =6678949 -> 6678949 | F29: =9824928 -> 9824928 | G29: =15126901 -> 15126901 | H29: =14239592 -> 14239592 | I29: =11467851 -> 11467851 | J29: =AVERAGE(G29:I29) -> 13611448 | K29: =AVERAGE(H29:J29) -> 13106297 | L29: =AVERAGE(I29:K29) -> 12728532 | M29: =AVERAGE(J29:L29) -> 13148759 | N29: =AVERAGE(K29:M29) -> 12994529
A31: % Growth of EBIT | F31: =F27/E27-1 -> 0.47102905 | G31: =G27/F27-1 -> 0.53964497 | H31: =H27/G27-1 -> -0.058657685 | I31: =I27/H27-1 -> -0.19465031 | J31: =_xlfn.NORM.INV(RAND(),I33,I35) -> 0.115515 | K31: =_xlfn.NORM.INV(RAND(),J33,J35) -> 0.1037702 | L31: =_xlfn.NORM.INV(RAND(),K33,K35) -> 0.78902732 | M31: =_xlfn.NORM.INV(RAND(),L33,L35) -> 0.12890438 | N31: =_xlfn.NORM.INV(RAND(),M33,M35) -> -0.10630863
A33: Mean % Growth of EBIT | F33: =AVERAGE($E$31:F31) -> 0.47102905 | G33: =AVERAGE($E$31:G31) -> 0.50533701 | H33: =AVERAGE($E$31:H31) -> 0.31733878 | I33: =AVERAGE($E$31:I31) -> 0.18934151 | J33: =AVERAGE($E$31:J31) -> 0.17457621 | K33: =AVERAGE($E$31:K31) -> 0.1627752 | L33: =AVERAGE($E$31:L31) -> 0.25223979 | M33: =AVERAGE($E$31:M31) -> 0.23682287 | N33: =AVERAGE($E$31:N31) -> 0.19869714
A35: Standard Deviation of % Growth of EBIT | F35: =_xlfn.STDEV.P($E$31:F31) -> 0 | G35: =_xlfn.STDEV.P($E$31:G31) -> 0.034307961 | H35: =_xlfn.STDEV.P($E$31:H31) -> 0.26734128 | I35: =_xlfn.STDEV.P($E$31:I31) -> 0.32055175 | J35: =_xlfn.STDEV.P($E$31:J31) -> 0.28822699 | K35: =_xlfn.STDEV.P($E$31:K31) -> 0.26443395 | L35: =_xlfn.STDEV.P($E$31:L31) -> 0.32857185 | M35: =_xlfn.STDEV.P($E$31:M31) -> 0.31004564 | N35: =_xlfn.STDEV.P($E$31:N31) -> 0.31157012
A37: EBIT Margin (%) | F37: =F27/F3 -> 0.068933543 | G37: =G27/G3 -> 0.092995009 | H37: =H27/H3 -> 0.081261761 | I37: =I27/I3 -> 0.061570877 | J37: =J27/J3 -> 0.063915197 | K37: =K27/K3 -> 0.070040417 | L37: =L27/L3 -> 0.10868299 | M37: =M27/M3 -> 0.11192238 | N37: =N27/N3 -> 0.082068547
A39: Tax Rate (Assume Tax Rate is Constant from 2026) | D39: 0.266 | E39: 0.214 | F39: 0.272 | G39: 0.281 | H39: 0.342 | I39: 0.223 | J39: =AVERAGE(D39:I39) -> 0.26633333 | K39: =AVERAGE(E39:J39) -> 0.26638889 | L39: =AVERAGE(F39:K39) -> 0.27512037 | M39: =AVERAGE(G39:L39) -> 0.27564043 | N39: =AVERAGE(H39:M39) -> 0.27474717
A42: Balance Sheet | D42: 2020 | E42: 2021 | F42: 2022 | G42: 2023 | H42: 2024 | I42: 2025 | J42: 2026 | K42: 2027 | L42: 2028 | M42: 2029 | N42: 2030
A44: ASSETS
A46: Trade Notes/Accounts Receivables (Rev/DSO*365) | D46: 3283972 | E46: 3147296 | F46: 4279057 | G46: 4682182 | H46: 5908079 | I46: 8600419 | J46: =J3*J7/365 -> 8894551.8 | K46: =K3*K7/365 -> 9542971.3 | L46: =L3*L7/365 -> 11433134 | M46: =M3*M7/365 -> 11972530 | N46: =N3*N7/365 -> 14855813
A48: Inventory (COS/DIO*365) | D48: 11333734 | E48: 11645641 | F48: 14291216 | G48: 17400346 | H48: 19791007 | I48: 20661752 | J48: =J5*J8/365 -> 22753807 | K48: =K5*K8/365 -> 26007298 | L48: =L5*L8/365 -> 28982374 | M48: =M5*M8/365 -> 32252241 | N48: =N5*N8/365 -> 36316842
A50: Other Current Assets (Revenue * Last 3 yrs OCA/Revenue) | D50: 2033371 | E50: 2081853 | F50: 2640553 | G50: 3150939 | H50: 3799870 | I50: 3870656 | J50: =I50/I3*J3 -> 4159404.8 | K50: =J50/J3*K3 -> 4189529.7 | L50: =K50/K3*L3 -> 4830247.4 | M50: =L50/L3*M3 -> 5295063.9 | N50: =M50/M3*N3 -> 6453554
A54: LIABILITY
A56: Accounts Payable (DPO/COS)*365 | D56: 8793179 | E56: 9155255 | F56: 10797065 | G56: 10952046 | H56: 12549646 | I56: 12287387 | J56: =J5*J9/365 -> 14098028 | K56: =K5*K9/365 -> 16030974 | L56: =L5*L9/365 -> 17688018 | M56: =M5*M9/365 -> 19849214 | N56: =N5*N9/365 -> 22300558
A57: Other Payables (Taken average of 3 years) | D57: 6123714 | E57: 6335645 | F57: 8277891 | G57: 8642808 | H57: 9532876 | I57: 9774921 | J57: =AVERAGE(G57:I57) -> 9316868.3 | K57: =AVERAGE(H57:J57) -> 9541555.1 | L57: =AVERAGE(I57:K57) -> 9544448.1 | M57: =AVERAGE(J57:L57) -> 9467623.9 | N57: =AVERAGE(K57:M57) -> 9517875.7
A58: Other Operating Current Liabilities (3 Year avg of OOCL / 3 Yr of avg of Rev)*Forecast Rev | D58: 7292585 | E58: 7440120 | F58: 8600241 | G58: 10577033 | H58: 11459928 | I58: 14675349 | J58: =AVERAGE(G58:I58)/AVERAGE(G3:I3)*J3 -> 14018776 | K58: =AVERAGE(H58:J58)/AVERAGE(H3:J3)*K3 -> 14413284 | L58: =AVERAGE(I58:K58)/AVERAGE(I3:K3)*L3 -> 17039806 | M58: =AVERAGE(J58:L58)/AVERAGE(J3:L3)*M3 -> 18269453 | N58: =AVERAGE(K58:M58)/AVERAGE(K3:M3)*N3 -> 22416394
A62: NET WORKING CAPITAL (NWC) | D62: =SUM(D46:D50)-SUM(D56:D58) -> -5558401 | E62: =SUM(E46:E50)-SUM(E56:E58) -> -6056230 | F62: =SUM(F46:F50)-SUM(F56:F58) -> -6464371 | G62: =SUM(G46:G50)-SUM(G56:G58) -> -4938420 | H62: =SUM(H46:H50)-SUM(H56:H58) -> -4043494 | I62: =SUM(I46:I50)-SUM(I56:I58) -> -3604830 | J62: =SUM(J46:J50)-SUM(J56:J58) -> -1625909 | K62: =SUM(K46:K50)-SUM(K56:K58) -> -246014.42 | ... N62: =SUM(N46:N50)-SUM(N56:N58) -> 3391381.9
A64: CHANGE IN NWC | E64: =E62-D62 -> -497829 | F64: =F62-E62 -> -408141 | G64: =G62-F62 -> 1525951 | H64: =H62-G62 -> 894926 | I64: =I62-H62 -> 438664 | J64: =J62-I62 -> 1978921 | K64: =K62-J62 -> 1379894.6 | L64: =L62-K62 -> 1219496.9 | ... N64: =N62-M62 -> 1457837.6
A65: % of Sales | D65: =D64/D3 -> 0 | E65: =E64/E3 -> -0.0042328573 | F65: =F64/F3 -> -0.002863594 | G65: =G64/G3 -> 0.0093810244 | H65: =H64/H3 -> 0.005107117 | I65: =I64/I3 -> 0.0023551864 | J65: =J64/J3 -> 0.0098872413 | K65: =K64/K3 -> 0.0068447645 | ... N65: =N64/N3 -> 0.0046944863
A68: Cash Flow Statement | D68: 2020 | E68: 2021 | F68: 2022 | G68: 2023 | H68: 2024 | I68: 2025 | J68: 2026 | K68: 2027 | L68: 2028 | M68: 2029 | N68: 2030
A71: Depreciation/Amortisation | D71: =2749513+1435860 -> 4185373 | E71: =2937914+1617823 -> 4555737 | F71: =3180687+1866935 -> 5047622 | G71: =3283730+1662765 -> 4946495 | H71: =3397606+889400 -> 4287006 | I71: =3744754+1271730 -> 5016484 | J71: =I71*(1+J73) -> 5248869.2 | K71: =J71*(1+K73) -> 5492019.4 | L71: =K71*(1+L73) -> 5746433.4 | M71: =L71*(1+M73) -> 6012633 | N71: =M71*(1+N73) -> 6291164.1
A72: Growth of Depreciation/Amortisation (%) | E72: =E71/D71-1 -> 0.088490082 | F72: =F71/E71-1 -> 0.10797046 | G72: =G71/F71-1 -> -0.020034583 | H72: =H71/G71-1 -> -0.13332451 | I72: =I71/H71-1 -> 0.17016025
A73: Average Growth (Assume constant Geometric Growth) | E73: =AVERAGE(E72) -> 0.088490082 | F73: =((1+F72)*(1+E72))^(1/2)-1 -> 0.098187075 | G73: =((1+G72)*(1+F72)*(1+E72))^(1/3)-1 -> 0.057274608 | H73: =((1+H72)*(1+G72)*(1+F72)*(1+E72))^(1/4)-1 -> 0.006016215 | I73: =((1+I72)*(1+H72)*(1+G72)*(1+F72)*(1+E72))^(1/4)-1 -> 0.04632431 | J73: =((1+I72)*(1+H72)*(1+G72)*(1+F72)*(1+E72))^(1/4)-1 -> 0.04632431 | K73: =((1+I72)*(1+H72)*(1+G72)*(1+F72)*(1+E72))^(1/4)-1 -> 0.04632431 | L73: =((1+I72)*(1+H72)*(1+G72)*(1+F72)*(1+E72))^(1/4)-1 -> 0.04632431 | M73: =((1+I72)*(1+H72)*(1+G72)*(1+F72)*(1+E72))^(1/4)-1 -> 0.04632431 | N73: =((1+I72)*(1+H72)*(1+G72)*(1+F72)*(1+E72))^(1/4)-1 -> 0.04632431
A75: % of Sales | D75: =D71/D3 -> 0.039579334 | E75: =E71/E3 -> 0.03873576 | F75: =F71/F3 -> 0.035415066 | G75: =G71/G3 -> 0.030409358 | H75: =H71/H3 -> 0.024464862 | I75: =I71/I3 -> 0.026933496 | J75: =J71/J3 -> 0.026224815 | K75: =K71/K3 -> 0.027242356 | ... N75: =N71/N3 -> 0.020258624
A78: Capital Expenditure | D78: =4687842+1701608 -> 6389450 | E78: =4304334+1556993 -> 5861327 | F78: =4014969+1718733 -> 5733702 | G78: =7070758+1780423 -> 8851181 | H78: =8061333+2306122 -> 10367455 | I78: =2703092+8366764 -> 11069856 | J78: =J3*J79 -> 11542758 | K78: =K3*K79 -> 11845214 | L78: =L3*L79 -> 13625128 | M78: =M3*M79 -> 14867179 | N78: =N3*N79 -> 18190145
A79: % of Sales | D79: =D78/D3 -> 0.060422375 | E79: =E78/E3 -> 0.049836713 | F79: =F78/F3 -> 0.040228732 | G79: =G78/G3 -> 0.054414031 | H79: =H78/H3 -> 0.059164451 | I79: =I78/I3 -> 0.059434042 | J79: =AVERAGE(G79:I79) -> 0.057670841 | K79: =AVERAGE(H79:J79) -> 0.058756445 | L79: =AVERAGE(I79:K79) -> 0.058620443 | M79: =AVERAGE(J79:L79) -> 0.058349243 | N79: =AVERAGE(K79:M79) -> 0.058575377
...

Sheet WACC
B1: WACC
B4: YEARS | C4: 2020 | D4: 2021 | E4: 2022 | F4: 2023 | G4: 2024 | H4: 2025
B6: RATIOS
B7: Total Equity E | C7: 76340970 | D7: 82615789 | E7: 90896545 | F7: 101809440 | G7: 120275933 | H7: 127648237
B9: Total Debt (D) | C9: =Data!F10 -> 133003242 | D9: =Data!G10 -> 151330626 | E9: =Data!H10 -> 164845917 | F9: =Data!I10 -> 180653915 | G9: =Data!J10 -> 219522496 | H9: =Data!K10 -> 241196612
B11: Total Value (V) | C11: =C7+C9 -> 209344212 | D11: =D7+D9 -> 233946415 | E11: =E7+E9 -> 255742462 | F11: =F7+F9 -> 282463355 | G11: =G7+G9 -> 339798429 | H11: =H7+H9 -> 368844849
B13: D/V Ratio | C13: =C9/C11 -> 0.63533279 | D13: =D9/D11 -> 0.64686021 | E13: =E9/E11 -> 0.64457781 | F13: =F9/F11 -> 0.63956585 | G13: =G9/G11 -> 0.64603741 | H13: =H9/H11 -> 0.65392431
B15: E/V Ratio | C15: =C7/C11 -> 0.36466721 | D15: =D7/D11 -> 0.35313979 | E15: =E7/E11 -> 0.35542219 | F15: =F7/F11 -> 0.36043415 | G15: =G7/G11 -> 0.35396259 | H15: =H7/H11 -> 0.34607569
J18: =C25*(1-C19) -> 0
B19: Corporate Tax Rate (Business Korea 2020 and rest are from FinBox) | C19: 0.229 | D19: 0.285 | E19: 0.266 | F19: 0.263 | G19: 0.238 | H19: 0.251
B22: Costs of Debt/Equity
B24: COST OF DEBT
B26: Before-Tax Cost of Debt (Interest Expense/Total Debt) | C26: =362377/C$9 -> 0.0027245727 | D26: =362377/D$9 -> 0.0023946045 | E26: =362377/E$9 -> 0.0021982771 | F26: =362377/F$9 -> 0.0020059183 | G26: =362377/G$9 -> 0.0016507511 | H26: =362377/H$9 -> 0.0015024133
B27: After-Tax Cost of Debt | C27: =C26*(1-C19) -> 0.0021006455 | D27: =D26*(1-D19) -> 0.0017121422 | E27: =E26*(1-E19) -> 0.0016135354 | F27: =F26*(1-F19) -> 0.0014783618 | G27: =G26*(1-G19) -> 0.0012578723 | H27: =H26*(1-H19) -> 0.0011253076
B29: Cost of Equity
B31: Risk Free Rate | C31: =0.0438 -> 0.0438
B33: Market Risk Premium (Alphaspread and assume it's constant) | C33: 0.043
B35: Beta (Value Investing) | C35: =1.73 -> 1.73
B37: Cost of Equity | C37: =C31+$C$33*$C$31 -> 0.0456834
B40: WACC | C40: =C13*C27+C15*C37 -> 0.017993847
B42: WACC From Alphaspread | C42: 0.0738

Sheet Share Prices
A1: Hyundai Motor Stock Price History
A2: Date | B2: Price | C2: Open | D2: High | E2: Low | F2: Vol. | G2: Change %
A3: 46259 | B3: 421000 | C3: 422000 | D3: 427250 | E3: 406000 | F3: 570.22K | G3: 0.0169
A4: 46258 | B4: 414000 | C4: 416000 | D4: 420000 | E4: 408000 | F4: 349.74K | G4: -0.0024
A5: 46255 | B5: 415000 | C5: 406500 | D5: 420500 | E5: 405000 | F5: 371.71K | G5: -0.006
A6: 46254 | B6: 417500 | C6: 417000 | D6: 425000 | E6: 408000 | F6: 421.24K | G6: 0.0085
A7: 46253 | B7: 414000 | C7: 416000 | D7: 422500 | E7: 406500 | F7: 533.27K | G7: -0.0483
A8: 46252 | B8: 435000 | C8: 459500 | D8: 459500 | E8: 427000 | F8: 864.88K | G8: -0.0397
A9: 46248 | B9: 453000 | C9: 424000 | D9: 456000 | E9: 421500 | F9: 1.20M | G9: 0.0824
A10: 46247 | B10: 418500 | C10: 419500 | D10: 431500 | E10: 415000 | F10: 590.76K | G10: 0.022
A11: 46246 | B11: 409500 | C11: 403000 | D11: 413000 | E11: 400500 | F11: 411.57K | G11: 0.0161
A12: 46245 | B12: 403000 | C12: 406000 | D12: 411000 | E12: 400500 | F12: 327.06K | G12: -0.0123
A13: 46244 | B13: 408000 | C13: 396000 | D13: 410500 | E13: 392500 | F13: 458.58K | G13: 0.0316
A14: 46241 | B14: 395500 | C14: 401000 | D14: 406000 | E14: 387000 | F14: 415.67K | G14: -0.0113
... A602: 45362 | B602: 243500 | C602: 251000 | D602: 252500 | E602: 242000 | F602: 1.17M | G602: -0.0375
A603: 45361 | B603: 253000 | C603: 253000 | D603: 253000 | E603: 253000 | G603: 0
A604: 45359 | B604: 253000 | C604: 251500 | D604: 255000 | E604: 249500 | F604: 1.20M | G604: 0.012
A605: 45358 | B605: 250000 | C605: 252500 | D605: 258000 | E605: 247500 | F605: 983.20K | G605: -0.004
A606: 45357 | B606: 251000 | C606: 247000 | D606: 254000 | E606: 246000 | F606: 1.09M | G606: 0.008
A607: 45356 | B607: 249000 | C607: 251500 | D607: 254500 | E607: 247500 | F607: 1.43M | G607: -0.0254
A608: 45355 | B608: 255500 | C608: 255500 | D608: 260000 | E608: 253000 | F608: 1.84M | G608: 0.02
A609: 45354 | B609: 250500 | C609: 250500 | D609: 250500 | E609: 250500 | G609: 0
A610: 45351 | B610: 250500 | C610: 246500 | D610: 253500 | E610: 243500 | F610: 2.03M | G610: 0.0101
A611: 45350 | B611: 248000 | C611: 234000 | D611: 250000 | E611: 231500 | F611: 1.90M | G611: 0.0398
A612: 45349 | B612: 238500 | C612: 239000 | D612: 244500 | E612: 237500 | F612: 1.24M | G612: -0.0021
A613: 45348 | B613: 239000 | C613: 237500 | D613: 241000 | E613: 231500 | F613: 1.74M | G613: -0.0205
A614: 45347 | B614: 244000 | C614: 244000 | D614: 244000 | E614: 244000 | G614: 0
A615: 45345 | B615: 244000 | C615: 244000 | D615: 249500 | E615: 242000 | F615: 1.64M | G615: 0.0021
A616: 45344 | B616: 243500 | C616: 239000 | D616: 245500 | E616: 237500 | F616: 1.47M | G616: 0.0167
A617: 45343 | B617: 239500 | C617: 242000 | D617: 246000 | E617: 237500 | F617: 1.13M | G617: -0.0103
A618: 45342 | B618: 242000 | C618: 250000 | D618: 253000 | E618: 238500 | F618: 1.91M | G618: -0.0416
A619: 45341 | B619: 252500 | C619: 253500 | D619: 257000 | E619: 248500 | F619: 1.78M | G619: 0
A620: 45340 | B620: 252500 | C620: 252500 | D620: 252500 | E620: 252500 | G620: 0
A621: 45338 | B621: 252500 | C621: 241500 | D621: 253000 | E621: 235500 | F621: 2.23M | G621: 0.0521
A622: 45337 | B622: 240000 | C622: 250000 | D622: 250500 | E622: 237000 | F622: 2.09M | G622: -0.0224
A623: 45336 | B623: 245500 | C623: 245000 | D623: 251000 | E623: 244500 | F623: 1.67M | G623: -0.0141
A624: 45335 | B624: 249000 | C624: 251000 | D624: 261000 | E624: 247500 | F624: 2.66M | G624: -0.004
A625: 45334 | B625: 250000 | C625: 250000 | D625: 250000 | E625: 250000 | G625: 0
A626: 45330 | B626: 250000 | C626: 243000 | D626: 250500 | E626: 241500 | F626: 2.99M | G626: 0.0204
A627: 45329 | B627: 245000 | C627: 239000 | D627: 246500 | E627: 238000 | F627: 2.69M | G627: 0.0403
...

Sheet Monte Carlo Simulation
B2: Normally Distributed Random Variable of Forecasted Revenue | D2: 2021 | E2: 2022 | F2: 2023 | G2: 2024 | H2: 2025 | I2: 2026 | J2: 2027 | K2: 2028 | L2: 2029 | M2: 2030 | P2: TRIALS
B4: Mean % Growth of Revenue | D4: ='DCF Modelling'!E14 -> 0.11219485 | E4: ='DCF Modelling'!F14 -> 0.16202709 | F4: ='DCF Modelling'!G14 -> 0.15511082 | G4: ='DCF Modelling'!H14 -> 0.1356484 | H4: ='DCF Modelling'!I14 -> 0.12110018 | I4: ='DCF Modelling'!J14 -> 0.11335006 | J4: ='DCF Modelling'!K14 -> 0.098191847 | K4: ='DCF Modelling'!L14 -> 0.1050345 | ... M4: ='DCF Modelling'!N14 -> 0.11552932
B6: Standard Deviation of % Growth of Revenue | D6: ='DCF Modelling'!E16 -> 0 | E6: ='DCF Modelling'!F16 -> 0.049832242 | F6: ='DCF Modelling'!G16 -> 0.041846998 | G6: ='DCF Modelling'!H16 -> 0.049494805 | H6: ='DCF Modelling'!I16 -> 0.052975387 | I6: ='DCF Modelling'!J16 -> 0.051371018 | J6: ='DCF Modelling'!K16 -> 0.060337487 | K6: ='DCF Modelling'!L16 -> 0.059273007 | ... M6: ='DCF Modelling'!N16 -> 0.063262942
B8: Normally Distributed Random Variable of Forecasted Cost of Sales
B10: Mean % Growth of Cost of Sales | D10: ='DCF Modelling'!E21 -> 0.086145994 | E10: ='DCF Modelling'!F21 -> 0.13990267 | F10: ='DCF Modelling'!G21 -> 0.13695922 | G10: ='DCF Modelling'!H21 -> 0.12265831 | H10: ='DCF Modelling'!I21 -> 0.11612997 | I10: ='DCF Modelling'!J21 -> 0.11403824 | J10: ='DCF Modelling'!K21 -> 0.11707416 | K10: ='DCF Modelling'!L21 -> 0.11790992 | ... M10: ='DCF Modelling'!N21 -> 0.11777781
B12: Standard Deviation of % Growth of Cost of Sales | E12: ='DCF Modelling'!F23 -> 0.026878339 | F12: ='DCF Modelling'!G23 -> 0.024676637 | G12: ='DCF Modelling'!H23 -> 0.021382617 | H12: ='DCF Modelling'!I23 -> 0.019241744 | I12: ='DCF Modelling'!J23 -> 0.017722487 | J12: ='DCF Modelling'!K23 -> 0.016426407 | K12: ='DCF Modelling'!L23 -> 0.015369624 | L12: ='DCF Modelling'!M23 -> 0.014503168 | M12: ='DCF Modelling'!N23 -> 0.013761339
